<?xml version="1.0" ?>
<!-- =================================================================================== -->
<!-- |    This document was autogenerated by xacro from simple_arm.xacro               | -->
<!-- |    EDITING THIS FILE BY HAND IS NOT RECOMMENDED                                 | -->
<!-- =================================================================================== -->
<robot name="simple_arm_xacro">
  <!-- 定义颜色，用于rviz显示 -->
  <material name="blue">
    <color rgba="0 0 0.8 1"/>
  </material>
  <material name="red">
    <color rgba="0.8 0 0 1"/>
  </material>
  <!-- 基座 -->
  <link name="base_link">
    <visual>
      <geometry>
        <cylinder length="0.1" radius="0.2"/>
      </geometry>
      <material name="blue"/>
    </visual>
    <collision>
      <geometry>
        <cylinder length="0.1" radius="0.2"/>
      </geometry>
    </collision>
  </link>
  <!-- 连杆1 -->
  <link name="link_1">
    <visual>
      <geometry>
        <box size="0.1 0.1 0.4"/>
      </geometry>
      <origin rpy="0 0 0" xyz="0 0 0.2"/>
      <material name="red"/>
    </visual>
    <collision>
      <geometry>
        <box size="0.1 0.1 0.4"/>
      </geometry>
      <origin xyz="0 0 0.2"/>
    </collision>
  </link>
  <!-- 节点1（连接基座和连杆1） -->
  <joint name="joint_1" type="revolute">
    <parent link="base_link"/>
    <child link="link_1"/>
    <origin rpy="0 0 0" xyz="0 0 0.05"/>
    <axis xyz="0 1 0"/>
    <limit effort="10" lower="-1.0" upper="1.0" velocity="1"/>
  </joint>
  <!-- 连杆2 -->
  <link name="link_2">
    <visual>
      <origin rpy="0 0 0" xyz="0 0 0.15"/>
      <geometry>
        <cylinder length="0.3" radius="0.05"/>
      </geometry>
      <material name="blue"/>
    </visual>
    <collision>
      <origin rpy="0 0 0" xyz="0 0 0.15"/>
      <geometry>
        <cylinder length="0.3" radius="0.05"/>
      </geometry>
    </collision>
  </link>
  <!-- 节点2（连接连杆1和连杆2） -->
  <joint name="joint_2" type="revolute">
    <parent link="link_1"/>
    <child link="link_2"/>
    <origin rpy="0 0 0" xyz="0 0 0.4"/>
    <axis xyz="1 0 0"/>
    <limit effort="10" lower="-1.5707963267948966" upper="1.5707963267948966" velocity="1"/>
  </joint>
</robot>

